Workbook

Sheet Scores
A1: PredictionDate | B1: PredictionTime | C1: Weekday | D1: GameDate | E1: GameTime | F1: GameID | G1: AwayTeam | H1: HomeTeam | I1: PredictedAwayScore | J1: PredictedHomeScore | K1: PredictedResult | L1: PredictedWinner | M1: ActualAwayScore | N1: ActualHomeScore | O1: ActualResult | P1: ActualWinner | Q1: WatchedGame | R1: WatchDate | S1: WatchTime | T1: ActualLoser | U1: AwayGameGoalDiff | V1: HomeGameGoalDiff | W1: GamePredictionPoints1 | X1: GamePredictionPoints2 | Y1: GamePredictionPoints3 | Z1: AwayGoalDiffDay | AA1: HomeGoalDiffDay | AB1: GameIsOver | AC1: CorrectWinnerPrediction | AD1: CorrectAwayScorePrediction | AE1: CorrectHomeScorePrediction | AF1: AwayShutout | AG1: HomeShutout | AH1: AwayWon | AI1: HomeWon | AJ1: InterConf | AK1: InterDiv | AL1: SameConfDiffDiv | AM1: CrossConf | AN1: AwayRecordAll | AO1: AwayRecordVSHome | AP1: HomeRecordAll | AQ1: HomeRecordVSAway
A2: 45937 | B2: 1620 | C2: =IF(WEEKDAY(Table1[[#This Row],[GameDate]])=1,"SUN",IF(WEEKDAY(Table1[[#This Row],[GameDate]])=2,"MON",IF(WEEKDAY(Table1[[#This Row],[GameDate]])=3,"TUE",IF(WEEKDAY(Table1[[#This Row],[GameDate]])=4,"WED",IF(WEEKDAY(Table1[[#This Row],[GameDate]])=5,"THU",IF(WEEKDAY(Table1[[#This Row],[GameDate]])=6,"FRI", "SAT")))))) -> TUE | D2: 2026-09-29 | E2: 18:00 | F2: 2026020001 | G2: FLA | H2: CAR | I2: 8 | J2: 9 | K2: REG | L2: =IF(OR(Table1[[#This Row],[PredictedAwayScore]]=Table1[[#This Row],[PredictedHomeScore]],AND(ISBLANK(Table1[[#This Row],[PredictedAwayScore]]),ISBLANK(Table1[[#This Row],[PredictedHomeScore]]))),"",IF(Table1[[#This Row],[PredictedAwayScore]]>Table1[[#This Row],[PredictedHomeScore]],Table1[[#This Row],[AwayTeam]],Table1[[#This Row],[HomeTeam]])) -> CAR | M2: 6 | N2: 3 | O2: REG | P2: =IF(OR(Table1[[#This Row],[ActualAwayScore]]=Table1[[#This Row],[ActualHomeScore]],AND(ISBLANK(Table1[[#This Row],[ActualAwayScore]]),ISBLANK(Table1[[#This Row],[ActualHomeScore]]))),"",IF(Table1[[#This Row],[ActualAwayScore]]>Table1[[#This Row],[ActualHomeScore]],Table1[[#This Row],[AwayTeam]], Table1[[#This Row],[HomeTeam]])) -> FLA | Q2: 1 | R2: 45937 | S2: 2000 | T2: =IF(Table1[[#This Row],[ActualWinner]]="", "", IF(Table1[[#This Row],[AwayTeam]]=Table1[[#This Row],[ActualWinner]],Table1[[#This Row],[HomeTeam]],Table1[[#This Row],[AwayTeam]])) -> CAR | U2: =Table1[[#This Row],[ActualAwayScore]]-Table1[[#This Row],[PredictedAwayScore]] -> -2 | V2: =Table1[[#This Row],[ActualHomeScore]]-Table1[[#This Row],[PredictedHomeScore]] -> -6 | W2: =(0.8*IF(Table1[[#This Row],[CorrectWinnerPrediction]]=1, 1, 0))+(0.1*IF(Table1[[#This Row],[CorrectAwayScorePrediction]]=1, 1, 0))+(0.1*IF(Table1[[#This Row],[CorrectHomeScorePrediction]]=1, 1, 0)) -> 0 | X2: =(0.8*IF(Table1[[#This Row],[CorrectWinnerPrediction]]=1, 1, 0))+(0.1*IF(Table1[[#This Row],[CorrectAwayScorePrediction]]=1, 1, 0))+(0.1*IF(Table1[[#This Row],[CorrectHomeScorePrediction]]=1, 1, 0)) + (0.8 * IF(OR(Table1[[#This Row],[PredictedResult]]="REG",Table1[[#This Row],[CorrectWinnerPrediction]]=1), 0, IF(Table1[[#This Row],[ActualResult]]="OT", 0.85, IF(Table1[[#This Row],[ActualResult]]="SO", 0.95, 0)))) -> 0 | Z2: =SUMIF(Table1[GameDate], Table1[[#This Row],[GameDate]], Table1[AwayGameGoalDiff]) -> 2 | AA2: =SUMIF(Table1[GameDate], Table1[[#This Row],[GameDate]], Table1[HomeGameGoalDiff]) -> -8 | AB2: =IF(ISBLANK(Table1[[#This Row],[ActualResult]]), 0, 1) -> 1 | AC2: =IF(ISBLANK(Table1[[#This Row],[ActualResult]]), 0, IF(Table1[[#This Row],[ActualWinner]]=Table1[[#This Row],[PredictedWinner]], 1, 0)) -> 0 | AD2: =IF(Table1[[#This Row],[ActualAwayScore]]>Table1[[#This Row],[PredictedAwayScore]], 0, IF(ISBLANK(Table1[[#This Row],[ActualResult]]), 0, IF(Table1[[#This Row],[ActualAwayScore]]=Table1[[#This Row],[PredictedAwayScore]], 1,0))) -> 0 | AE2: =IF(Table1[[#This Row],[ActualHomeScore]]>Table1[[#This Row],[PredictedHomeScore]], 0, IF(ISBLANK(Table1[[#This Row],[ActualResult]]), 0, IF(Table1[[#This Row],[ActualHomeScore]]=Table1[[#This Row],[PredictedHomeScore]], 1, 0))) -> 0 | AF2: =IF(AND(Table1[[#This Row],[GameIsOver]]=1,Table1[[#This Row],[ActualAwayScore]]=0), 1,0) -> 0 | AG2: =IF(AND(Table1[[#This Row],[GameIsOver]]=1,Table1[[#This Row],[ActualHomeScore]]=0), 1,0) -> 0 | AH2: =IF(Table1[[#This Row],[GameIsOver]]=0,0,IF(Table1[[#This Row],[ActualWinner]]=Table1[[#This Row],[AwayTeam]], 1, 0)) -> 1 | AI2: =IF(Table1[[#This Row],[GameIsOver]]=0,0,IF(Table1[[#This Row],[ActualWinner]]=Table1[[#This Row],[HomeTeam]], 1, 0)) -> 0 | AJ2: =IF(INDEX(Standings!$A$2:$C$33,MATCH(Table1[[#This Row],[AwayTeam]],Standings!$A$2:$A$33,0),2)=INDEX(Standings!$A$2:$C$33,MATCH(Table1[[#This Row],[HomeTeam]],Standings!$A$2:$A$33,0),2),1,0) -> 1 | AK2: =IF(INDEX(Standings!$A$2:$C$33,MATCH(Table1[[#This Row],[AwayTeam]],Standings!$A$2:$A$33,0),3)=INDEX(Standings!$A$2:$C$33,MATCH(Table1[[#This Row],[HomeTeam]],Standings!$A$2:$A$33,0),3),1,0) -> 0 | AL2: =IF(Table1[[#This Row],[InterConf]]=1,IF(Table1[[#This Row],[InterDiv]]=0, 1, 0), 0) -> 1 | AM2: =IF(INDEX(Standings!$A$2:$C$33,MATCH(Table1[[#This Row],[AwayTeam]],Standings!$A$2:$A$33,0),2)<>INDEX(Standings!$A$2:$C$33,MATCH(Table1[[#This Row],[HomeTeam]],Standings!$A$2:$A$33,0),2),1,0) -> 0 | AN2: =INDEX(Table2[AWAY_RECORD], MATCH(Table1[[#This Row],[AwayTeam]],Table2[Team], 0), 0) -> 2-0-0 | AO2: =INDEX(Records!$B$2:$AG$33, MATCH(Table1[[#This Row],[AwayTeam]],Records!$A$2:$A$33, 0), MATCH(Table1[[#This Row],[HomeTeam]],Records!$A$2:$A$33, 0)) -> 1-0-0 | AP2: =INDEX(Table2[HOME_RECORD], MATCH(Table1[[#This Row],[HomeTeam]],Table2[Team], 0), 0) -> 1-1-0 | AQ2: =INDEX(Records!$B$2:$AG$33, MATCH(Table1[[#This Row],[HomeTeam]],Records!$A$2:$A$33, 0), MATCH(Table1[[#This Row],[AwayTeam]],Records!$A$2:$A$33, 0)) -> 0-1-0
C3: =IF(WEEKDAY(Table1[[#This Row],[GameDate]])=1,"SUN",IF(WEEKDAY(Table1[[#This Row],[GameDate]])=2,"MON",IF(WEEKDAY(Table1[[#This Row],[GameDate]])=3,"TUE",IF(WEEKDAY(Table1[[#This Row],[GameDate]])=4,"WED",IF(WEEKDAY(Table1[[#This Row],[GameDate]])=5,"THU",IF(WEEKDAY(Table1[[#This Row],[GameDate]])=6,"FRI", "SAT")))))) -> TUE | D3: 2026-09-29 | E3: 20:00 | F3: 2026020002 | G3: MTL | H3: TOR | I3: 1 | J3: 3 | K3: SO | L3: =IF(OR(Table1[[#This Row],[PredictedAwayScore]]=Table1[[#This Row],[PredictedHomeScore]],AND(ISBLANK(Table1[[#This Row],[PredictedAwayScore]]),ISBLANK(Table1[[#This Row],[PredictedHomeScore]]))),"",IF(Table1[[#This Row],[PredictedAwayScore]]>Table1[[#This Row],[PredictedHomeScore]],Table1[[#This Row],[AwayTeam]],Table1[[#This Row],[HomeTeam]])) -> TOR | M3: 4 | N3: 3 | O3: REG | P3: =IF(OR(Table1[[#This Row],[ActualAwayScore]]=Table1[[#This Row],[ActualHomeScore]],AND(ISBLANK(Table1[[#This Row],[ActualAwayScore]]),ISBLANK(Table1[[#This Row],[ActualHomeScore]]))),"",IF(Table1[[#This Row],[ActualAwayScore]]>Table1[[#This Row],[ActualHomeScore]],Table1[[#This Row],[AwayTeam]], Table1[[#This Row],[HomeTeam]])) -> MTL | T3: =IF(Table1[[#This Row],[ActualWinner]]="", "", IF(Table1[[#This Row],[AwayTeam]]=Table1[[#This Row],[ActualWinner]],Table1[[#This Row],[HomeTeam]],Table1[[#This Row],[AwayTeam]])) -> TOR | U3: =Table1[[#This Row],[ActualAwayScore]]-Table1[[#This Row],[PredictedAwayScore]] -> 3 | V3: =Table1[[#This Row],[ActualHomeScore]]-Table1[[#This Row],[PredictedHomeScore]] -> 0 | W3: =(0.8*IF(Table1[[#This Row],[CorrectWinnerPrediction]]=1, 1, 0))+(0.1*IF(Table1[[#This Row],[CorrectAwayScorePrediction]]=1, 1, 0))+(0.1*IF(Table1[[#This Row],[CorrectHomeScorePrediction]]=1, 1, 0)) -> 0.1 | X3: =(0.8*IF(Table1[[#This Row],[CorrectWinnerPrediction]]=1, 1, 0))+(0.1*IF(Table1[[#This Row],[CorrectAwayScorePrediction]]=1, 1, 0))+(0.1*IF(Table1[[#This Row],[CorrectHomeScorePrediction]]=1, 1, 0)) + (0.8 * IF(OR(Table1[[#This Row],[PredictedResult]]="REG",Table1[[#This Row],[CorrectWinnerPrediction]]=1), 0, IF(Table1[[#This Row],[ActualResult]]="OT", 0.85, IF(Table1[[#This Row],[ActualResult]]="SO", 0.95, 0)))) -> 0.1 | Z3: =SUMIF(Table1[GameDate], Table1[[#This Row],[GameDate]], Table1[AwayGameGoalDiff]) -> 2 | AA3: =SUMIF(Table1[GameDate], Table1[[#This Row],[GameDate]], Table1[HomeGameGoalDiff]) -> -8 | AB3: =IF(ISBLANK(Table1[[#This Row],[ActualResult]]), 0, 1) -> 1 | AC3: =IF(ISBLANK(Table1[[#This Row],[ActualResult]]), 0, IF(Table1[[#This Row],[ActualWinner]]=Table1[[#This Row],[PredictedWinner]], 1, 0)) -> 0 | AD3: =IF(Table1[[#This Row],[ActualAwayScore]]>Table1[[#This Row],[PredictedAwayScore]], 0, IF(ISBLANK(Table1[[#This Row],[ActualResult]]), 0, IF(Table1[[#This Row],[ActualAwayScore]]=Table1[[#This Row],[PredictedAwayScore]], 1,0))) -> 0 | AE3: =IF(Table1[[#This Row],[ActualHomeScore]]>Table1[[#This Row],[PredictedHomeScore]], 0, IF(ISBLANK(Table1[[#This Row],[ActualResult]]), 0, IF(Table1[[#This Row],[ActualHomeScore]]=Table1[[#This Row],[PredictedHomeScore]], 1, 0))) -> 1 | AF3: =IF(AND(Table1[[#This Row],[GameIsOver]]=1,Table1[[#This Row],[ActualAwayScore]]=0), 1,0) -> 0 | AG3: =IF(AND(Table1[[#This Row],[GameIsOver]]=1,Table1[[#This Row],[ActualHomeScore]]=0), 1,0) -> 0 | AH3: =IF(Table1[[#This Row],[GameIsOver]]=0,0,IF(Table1[[#This Row],[ActualWinner]]=Table1[[#This Row],[AwayTeam]], 1, 0)) -> 1 | AI3: =IF(Table1[[#This Row],[GameIsOver]]=0,0,IF(Table1[[#This Row],[ActualWinner]]=Table1[[#This Row],[HomeTeam]], 1, 0)) -> 0 | AJ3: =IF(INDEX(Standings!$A$2:$C$33,MATCH(Table1[[#This Row],[AwayTeam]],Standings!$A$2:$A$33,0),2)=INDEX(Standings!$A$2:$C$33,MATCH(Table1[[#This Row],[HomeTeam]],Standings!$A$2:$A$33,0),2),1,0) -> 1 | AK3: =IF(INDEX(Standings!$A$2:$C$33,MATCH(Table1[[#This Row],[AwayTeam]],Standings!$A$2:$A$33,0),3)=INDEX(Standings!$A$2:$C$33,MATCH(Table1[[#This Row],[HomeTeam]],Standings!$A$2:$A$33,0),3),1,0) -> 1 | AL3: =IF(Table1[[#This Row],[InterConf]]=1,IF(Table1[[#This Row],[InterDiv]]=0, 1, 0), 0) -> 0 | AM3: =IF(INDEX(Standings!$A$2:$C$33,MATCH(Table1[[#This Row],[AwayTeam]],Standings!$A$2:$A$33,0),2)<>INDEX(Standings!$A$2:$C$33,MATCH(Table1[[#This Row],[HomeTeam]],Standings!$A$2:$A$33,0),2),1,0) -> 0 | AN3: =INDEX(Table2[AWAY_RECORD], MATCH(Table1[[#This Row],[AwayTeam]],Table2[Team], 0), 0) -> 1-0-0 | AO3: =INDEX(Records!$B$2:$AG$33, MATCH(Table1[[#This Row],[AwayTeam]],Records!$A$2:$A$33, 0), MATCH(Table1[[#This Row],[HomeTeam]],Records!$A$2:$A$33, 0)) -> 1-0-0 | AP3: =INDEX(Table2[HOME_RECORD], MATCH(Table1[[#This Row],[HomeTeam]],Table2[Team], 0), 0) -> 0-2-0 | AQ3: =INDEX(Records!$B$2:$AG$33, MATCH(Table1[[#This Row],[HomeTeam]],Records!$A$2:$A$33, 0), MATCH(Table1[[#This Row],[AwayTeam]],Records!$A$2:$A$33, 0)) -> 0-1-0
C4: =IF(WEEKDAY(Table1[[#This Row],[GameDate]])=1,"SUN",IF(WEEKDAY(Table1[[#This Row],[GameDate]])=2,"MON",IF(WEEKDAY(Table1[[#This Row],[GameDate]])=3,"TUE",IF(WEEKDAY(Table1[[#This Row],[GameDate]])=4,"WED",IF(WEEKDAY(Table1[[#This Row],[GameDate]])=5,"THU",IF(WEEKDAY(Table1[[#This Row],[GameDate]])=6,"FRI", "SAT")))))) -> TUE | D4: 2026-09-29 | E4: 21:00 | F4: 2026020003 | G4: NYR | H4: BOS | I4: 3 | J4: 1 | K4: OT | L4: =IF(OR(Table1[[#This Row],[PredictedAwayScore]]=Table1[[#This Row],[PredictedHomeScore]],AND(ISBLANK(Table1[[#This Row],[PredictedAwayScore]]),ISBLANK(Table1[[#This Row],[PredictedHomeScore]]))),"",IF(Table1[[#This Row],[PredictedAwayScore]]>Table1[[#This Row],[PredictedHomeScore]],Table1[[#This Row],[AwayTeam]],Table1[[#This Row],[HomeTeam]])) -> NYR | M4: 3 | N4: 0 | O4: REG | P4: =IF(OR(Table1[[#This Row],[ActualAwayScore]]=Table1[[#This Row],[ActualHomeScore]],AND(ISBLANK(Table1[[#This Row],[ActualAwayScore]]),ISBLANK(Table1[[#This Row],[ActualHomeScore]]))),"",IF(Table1[[#This Row],[ActualAwayScore]]>Table1[[#This Row],[ActualHomeScore]],Table1[[#This Row],[AwayTeam]], Table1[[#This Row],[HomeTeam]])) -> NYR | T4: =IF(Table1[[#This Row],[ActualWinner]]="", "", IF(Table1[[#This Row],[AwayTeam]]=Table1[[#This Row],[ActualWinner]],Table1[[#This Row],[HomeTeam]],Table1[[#This Row],[AwayTeam]])) -> BOS | U4: =Table1[[#This Row],[ActualAwayScore]]-Table1[[#This Row],[PredictedAwayScore]] -> 0 | V4: =Table1[[#This Row],[ActualHomeScore]]-Table1[[#This Row],[PredictedHomeScore]] -> -1 | W4: =(0.8*IF(Table1[[#This Row],[CorrectWinnerPrediction]]=1, 1, 0))+(0.1*IF(Table1[[#This Row],[CorrectAwayScorePrediction]]=1, 1, 0))+(0.1*IF(Table1[[#This Row],[CorrectHomeScorePrediction]]=1, 1, 0)) -> 0.9 | X4: =(0.8*IF(Table1[[#This Row],[CorrectWinnerPrediction]]=1, 1, 0))+(0.1*IF(Table1[[#This Row],[CorrectAwayScorePrediction]]=1, 1, 0))+(0.1*IF(Table1[[#This Row],[CorrectHomeScorePrediction]]=1, 1, 0)) + (0.8 * IF(OR(Table1[[#This Row],[PredictedResult]]="REG",Table1[[#This Row],[CorrectWinnerPrediction]]=1), 0, IF(Table1[[#This Row],[ActualResult]]="OT", 0.85, IF(Table1[[#This Row],[ActualResult]]="SO", 0.95, 0)))) -> 0.9 | Z4: =SUMIF(Table1[GameDate], Table1[[#This Row],[GameDate]], Table1[AwayGameGoalDiff]) -> 2 | AA4: =SUMIF(Table1[GameDate], Table1[[#This Row],[GameDate]], Table1[HomeGameGoalDiff]) -> -8 | AB4: =IF(ISBLANK(Table1[[#This Row],[ActualResult]]), 0, 1) -> 1 | AC4: =IF(ISBLANK(Table1[[#This Row],[ActualResult]]), 0, IF(Table1[[#This Row],[ActualWinner]]=Table1[[#This Row],[PredictedWinner]], 1, 0)) -> 1 | AD4: =IF(Table1[[#This Row],[ActualAwayScore]]>Table1[[#This Row],[PredictedAwayScore]], 0, IF(ISBLANK(Table1[[#This Row],[ActualResult]]), 0, IF(Table1[[#This Row],[ActualAwayScore]]=Table1[[#This Row],[PredictedAwayScore]], 1,0))) -> 1 | AE4: =IF(Table1[[#This Row],[ActualHomeScore]]>Table1[[#This Row],[PredictedHomeScore]], 0, IF(ISBLANK(Table1[[#This Row],[ActualResult]]), 0, IF(Table1[[#This Row],[ActualHomeScore]]=Table1[[#This Row],[PredictedHomeScore]], 1, 0))) -> 0 | AF4: =IF(AND(Table1[[#This Row],[GameIsOver]]=1,Table1[[#This Row],[ActualAwayScore]]=0), 1,0) -> 0 | AG4: =IF(AND(Table1[[#This Row],[GameIsOver]]=1,Table1[[#This Row],[ActualHomeScore]]=0), 1,0) -> 1 | AH4: =IF(Table1[[#This Row],[GameIsOver]]=0,0,IF(Table1[[#This Row],[ActualWinner]]=Table1[[#This Row],[AwayTeam]], 1, 0)) -> 1 | AI4: =IF(Table1[[#This Row],[GameIsOver]]=0,0,IF(Table1[[#This Row],[ActualWinner]]=Table1[[#This Row],[HomeTeam]], 1, 0)) -> 0 | AJ4: =IF(INDEX(Standings!$A$2:$C$33,MATCH(Table1[[#This Row],[AwayTeam]],Standings!$A$2:$A$33,0),2)=INDEX(Standings!$A$2:$C$33,MATCH(Table1[[#This Row],[HomeTeam]],Standings!$A$2:$A$33,0),2),1,0) -> 1 | AK4: =IF(INDEX(Standings!$A$2:$C$33,MATCH(Table1[[#This Row],[AwayTeam]],Standings!$A$2:$A$33,0),3)=INDEX(Standings!$A$2:$C$33,MATCH(Table1[[#This Row],[HomeTeam]],Standings!$A$2:$A$33,0),3),1,0) -> 0 | AL4: =IF(Table1[[#This Row],[InterConf]]=1,IF(Table1[[#This Row],[InterDiv]]=0, 1, 0), 0) -> 1 | AM4: =IF(INDEX(Standings!$A$2:$C$33,MATCH(Table1[[#This Row],[AwayTeam]],Standings!$A$2:$A$33,0),2)<>INDEX(Standings!$A$2:$C$33,MATCH(Table1[[#This Row],[HomeTeam]],Standings!$A$2:$A$33,0),2),1,0) -> 0 | AN4: =INDEX(Table2[AWAY_RECORD], MATCH(Table1[[#This Row],[AwayTeam]],Table2[Team], 0), 0) -> 2-0-0 | AO4: =INDEX(Records!$B$2:$AG$33, MATCH(Table1[[#This Row],[AwayTeam]],Records!$A$2:$A$33, 0), MATCH(Table1[[#This Row],[HomeTeam]],Records!$A$2:$A$33, 0)) -> 1-0-0 | AP4: =INDEX(Table2[HOME_RECORD], MATCH(Table1[[#This Row],[HomeTeam]],Table2[Team], 0), 0) -> 0-1-0 | AQ4: =INDEX(Records!$B$2:$AG$33, MATCH(Table1[[#This Row],[HomeTeam]],Records!$A$2:$A$33, 0), MATCH(Table1[[#This Row],[AwayTeam]],Records!$A$2:$A$33, 0)) -> 0-1-0
C5: =IF(WEEKDAY(Table1[[#This Row],[GameDate]])=1,"SUN",IF(WEEKDAY(Table1[[#This Row],[GameDate]])=2,"MON",IF(WEEKDAY(Table1[[#This Row],[GameDate]])=3,"TUE",IF(WEEKDAY(Table1[[#This Row],[GameDate]])=4,"WED",IF(WEEKDAY(Table1[[#This Row],[GameDate]])=5,"THU",IF(WEEKDAY(Table1[[#This Row],[GameDate]])=6,"FRI", "SAT")))))) -> TUE | D5: 2026-09-29 | E5: 23:00 | F5: 2026020004 | G5: VAN | H5: EDM | I5: 3 | J5: 2 | K5: SO | L5: =IF(OR(Table1[[#This Row],[PredictedAwayScore]]=Table1[[#This Row],[PredictedHomeScore]],AND(ISBLANK(Table1[[#This Row],[PredictedAwayScore]]),ISBLANK(Table1[[#This Row],[PredictedHomeScore]]))),"",IF(Table1[[#This Row],[PredictedAwayScore]]>Table1[[#This Row],[PredictedHomeScore]],Table1[[#This Row],[AwayTeam]],Table1[[#This Row],[HomeTeam]])) -> VAN | M5: 1 | N5: 2 | O5: OT | P5: =IF(OR(Table1[[#This Row],[ActualAwayScore]]=Table1[[#This Row],[ActualHomeScore]],AND(ISBLANK(Table1[[#This Row],[ActualAwayScore]]),ISBLANK(Table1[[#This Row],[ActualHomeScore]]))),"",IF(Table1[[#This Row],[ActualAwayScore]]>Table1[[#This Row],[ActualHomeScore]],Table1[[#This Row],[AwayTeam]], Table1[[#This Row],[HomeTeam]])) -> EDM | T5: =IF(Table1[[#This Row],[ActualWinner]]="", "", IF(Table1[[#This Row],[AwayTeam]]=Table1[[#This Row],[ActualWinner]],Table1[[#This Row],[HomeTeam]],Table1[[#This Row],[AwayTeam]])) -> VAN | U5: =Table1[[#This Row],[ActualAwayScore]]-Table1[[#This Row],[PredictedAwayScore]] -> -2 | V5: =Table1[[#This Row],[ActualHomeScore]]-Table1[[#This Row],[PredictedHomeScore]] -> 0 | W5: =(0.8*IF(Table1[[#This Row],[CorrectWinnerPrediction]]=1, 1, 0))+(0.1*IF(Table1[[#This Row],[CorrectAwayScorePrediction]]=1, 1, 0))+(0.1*IF(Table1[[#This Row],[CorrectHomeScorePrediction]]=1, 1, 0)) -> 0.1 | X5: =(0.8*IF(Table1[[#This Row],[CorrectWinnerPrediction]]=1, 1, 0))+(0.1*IF(Table1[[#This Row],[CorrectAwayScorePrediction]]=1, 1, 0))+(0.1*IF(Table1[[#This Row],[CorrectHomeScorePrediction]]=1, 1, 0)) + (0.8 * IF(OR(Table1[[#This Row],[PredictedResult]]="REG",Table1[[#This Row],[CorrectWinnerPrediction]]=1), 0, IF(Table1[[#This Row],[ActualResult]]="OT", 0.85, IF(Table1[[#This Row],[ActualResult]]="SO", 0.95, 0)))) -> 0.78 | Z5: =SUMIF(Table1[GameDate], Table1[[#This Row],[GameDate]], Table1[AwayGameGoalDiff]) -> 2 | AA5: =SUMIF(Table1[GameDate], Table1[[#This Row],[GameDate]], Table1[HomeGameGoalDiff]) -> -8 | AB5: =IF(ISBLANK(Table1[[#This Row],[ActualResult]]), 0, 1) -> 1 | AC5: =IF(ISBLANK(Table1[[#This Row],[ActualResult]]), 0, IF(Table1[[#This Row],[ActualWinner]]=Table1[[#This Row],[PredictedWinner]], 1, 0)) -> 0 | AD5: =IF(Table1[[#This Row],[ActualAwayScore]]>Table1[[#This Row],[PredictedAwayScore]], 0, IF(ISBLANK(Table1[[#This Row],[ActualResult]]), 0, IF(Table1[[#This Row],[ActualAwayScore]]=Table1[[#This Row],[PredictedAwayScore]], 1,0))) -> 0 | AE5: =IF(Table1[[#This Row],[ActualHomeScore]]>Table1[[#This Row],[PredictedHomeScore]], 0, IF(ISBLANK(Table1[[#This Row],[ActualResult]]), 0, IF(Table1[[#This Row],[ActualHomeScore]]=Table1[[#This Row],[PredictedHomeScore]], 1, 0))) -> 1 | AF5: =IF(AND(Table1[[#This Row],[GameIsOver]]=1,Table1[[#This Row],[ActualAwayScore]]=0), 1,0) -> 0 | AG5: =IF(AND(Table1[[#This Row],[GameIsOver]]=1,Table1[[#This Row],[ActualHomeScore]]=0), 1,0) -> 0 | AH5: =IF(Table1[[#This Row],[GameIsOver]]=0,0,IF(Table1[[#This Row],[ActualWinner]]=Table1[[#This Row],[AwayTeam]], 1, 0)) -> 0 | AI5: =IF(Table1[[#This Row],[GameIsOver]]=0,0,IF(Table1[[#This Row],[ActualWinner]]=Table1[[#This Row],[HomeTeam]], 1, 0)) -> 1 | AJ5: =IF(INDEX(Standings!$A$2:$C$33,MATCH(Table1[[#This Row],[AwayTeam]],Standings!$A$2:$A$33,0),2)=INDEX(Standings!$A$2:$C$33,MATCH(Table1[[#This Row],[HomeTeam]],Standings!$A$2:$A$33,0),2),1,0) -> 1 | AK5: =IF(INDEX(Standings!$A$2:$C$33,MATCH(Table1[[#This Row],[AwayTeam]],Standings!$A$2:$A$33,0),3)=INDEX(Standings!$A$2:$C$33,MATCH(Table1[[#This Row],[HomeTeam]],Standings!$A$2:$A$33,0),3),1,0) -> 1 | AL5: =IF(Table1[[#This Row],[InterConf]]=1,IF(Table1[[#This Row],[InterDiv]]=0, 1, 0), 0) -> 0 | AM5: =IF(INDEX(Standings!$A$2:$C$33,MATCH(Table1[[#This Row],[AwayTeam]],Standings!$A$2:$A$33,0),2)<>INDEX(Standings!$A$2:$C$33,MATCH(Table1[[#This Row],[HomeTeam]],Standings!$A$2:$A$33,0),2),1,0) -> 0 | AN5: =INDEX(Table2[AWAY_RECORD], MATCH(Table1[[#This Row],[AwayTeam]],Table2[Team], 0), 0) -> 0-0-1 | AO5: =INDEX(Records!$B$2:$AG$33, MATCH(Table1[[#This Row],[AwayTeam]],Records!$A$2:$A$33, 0), MATCH(Table1[[#This Row],[HomeTeam]],Records!$A$2:$A$33, 0)) -> 0-0-2 | AP5: =INDEX(Table2[HOME_RECORD], MATCH(Table1[[#This Row],[HomeTeam]],Table2[Team], 0), 0) -> 1-0-0 | AQ5: =INDEX(Records!$B$2:$AG$33, MATCH(Table1[[#This Row],[HomeTeam]],Records!$A$2:$A$33, 0), MATCH(Table1[[#This Row],[AwayTeam]],Records!$A$2:$A$33, 0)) -> 2-0-0
C6: =IF(WEEKDAY(Table1[[#This Row],[GameDate]])=1,"SUN",IF(WEEKDAY(Table1[[#This Row],[GameDate]])=2,"MON",IF(WEEKDAY(Table1[[#This Row],[GameDate]])=3,"TUE",IF(WEEKDAY(Table1[[#This Row],[GameDate]])=4,"WED",IF(WEEKDAY(Table1[[#This Row],[GameDate]])=5,"THU",IF(WEEKDAY(Table1[[#This Row],[GameDate]])=6,"FRI", "SAT")))))) -> TUE | D6: 2026-09-29 | E6: 23:30 | F6: 2026020005 | G6: CHI | H6: VGK | I6: 1 | J6: 4 | K6: REG | L6: =IF(OR(Table1[[#This Row],[PredictedAwayScore]]=Table1[[#This Row],[PredictedHomeScore]],AND(ISBLANK(Table1[[#This Row],[PredictedAwayScore]]),ISBLANK(Table1[[#This Row],[PredictedHomeScore]]))),"",IF(Table1[[#This Row],[PredictedAwayScore]]>Table1[[#This Row],[PredictedHomeScore]],Table1[[#This Row],[AwayTeam]],Table1[[#This Row],[HomeTeam]])) -> VGK | M6: 4 | N6: 3 | O6: SO | P6: =IF(OR(Table1[[#This Row],[ActualAwayScore]]=Table1[[#This Row],[ActualHomeScore]],AND(ISBLANK(Table1[[#This Row],[ActualAwayScore]]),ISBLANK(Table1[[#This Row],[ActualHomeScore]]))),"",IF(Table1[[#This Row],[ActualAwayScore]]>Table1[[#This Row],[ActualHomeScore]],Table1[[#This Row],[AwayTeam]], Table1[[#This Row],[HomeTeam]])) -> CHI | T6: =IF(Table1[[#This Row],[ActualWinner]]="", "", IF(Table1[[#This Row],[AwayTeam]]=Table1[[#This Row],[ActualWinner]],Table1[[#This Row],[HomeTeam]],Table1[[#This Row],[AwayTeam]])) -> VGK | U6: =Table1[[#This Row],[ActualAwayScore]]-Table1[[#This Row],[PredictedAwayScore]] -> 3 | V6: =Table1[[#This Row],[ActualHomeScore]]-Table1[[#This Row],[PredictedHomeScore]] -> -1 | W6: =(0.8*IF(Table1[[#This Row],[CorrectWinnerPrediction]]=1, 1, 0))+(0.1*IF(Table1[[#This Row],[CorrectAwayScorePrediction]]=1, 1, 0))+(0.1*IF(Table1[[#This Row],[CorrectHomeScorePrediction]]=1, 1, 0)) -> 0 | X6: =(0.8*IF(Table1[[#This Row],[CorrectWinnerPrediction]]=1, 1, 0))+(0.1*IF(Table1[[#This Row],[CorrectAwayScorePrediction]]=1, 1, 0))+(0.1*IF(Table1[[#This Row],[CorrectHomeScorePrediction]]=1, 1, 0)) + (0.8 * IF(OR(Table1[[#This Row],[PredictedResult]]="REG",Table1[[#This Row],[CorrectWinnerPrediction]]=1), 0, IF(Table1[[#This Row],[ActualResult]]="OT", 0.85, IF(Table1[[#This Row],[ActualResult]]="SO", 0.95, 0)))) -> 0 | Z6: =SUMIF(Table1[GameDate], Table1[[#This Row],[GameDate]], Table1[AwayGameGoalDiff]) -> 2 | AA6: =SUMIF(Table1[GameDate], Table1[[#This Row],[GameDate]], Table1[HomeGameGoalDiff]) -> -8 | AB6: =IF(ISBLANK(Table1[[#This Row],[ActualResult]]), 0, 1) -> 1 | AC6: =IF(ISBLANK(Table1[[#This Row],[ActualResult]]), 0, IF(Table1[[#This Row],[ActualWinner]]=Table1[[#This Row],[PredictedWinner]], 1, 0)) -> 0 | AD6: =IF(Table1[[#This Row],[ActualAwayScore]]>Table1[[#This Row],[PredictedAwayScore]], 0, IF(ISBLANK(Table1[[#This Row],[ActualResult]]), 0, IF(Table1[[#This Row],[ActualAwayScore]]=Table1[[#This Row],[PredictedAwayScore]], 1,0))) -> 0 | AE6: =IF(Table1[[#This Row],[ActualHomeScore]]>Table1[[#This Row],[PredictedHomeScore]], 0, IF(ISBLANK(Table1[[#This Row],[ActualResult]]), 0, IF(Table1[[#This Row],[ActualHomeScore]]=Table1[[#This Row],[PredictedHomeScore]], 1, 0))) -> 0 | AF6: =IF(AND(Table1[[#This Row],[GameIsOver]]=1,Table1[[#This Row],[ActualAwayScore]]=0), 1,0) -> 0 | AG6: =IF(AND(Table1[[#This Row],[GameIsOver]]=1,Table1[[#This Row],[ActualHomeScore]]=0), 1,0) -> 0 | AH6: =IF(Table1[[#This Row],[GameIsOver]]=0,0,IF(Table1[[#This Row],[ActualWinner]]=Table1[[#This Row],[AwayTeam]], 1, 0)) -> 1 | AI6: =IF(Table1[[#This Row],[GameIsOver]]=0,0,IF(Table1[[#This Row],[ActualWinner]]=Table1[[#This Row],[HomeTeam]], 1, 0)) -> 0 | AJ6: =IF(INDEX(Standings!$A$2:$C$33,MATCH(Table1[[#This Row],[AwayTeam]],Standings!$A$2:$A$33,0),2)=INDEX(Standings!$A$2:$C$33,MATCH(Table1[[#This Row],[HomeTeam]],Standings!$A$2:$A$33,0),2),1,0) -> 1 | AK6: =IF(INDEX(Standings!$A$2:$C$33,MATCH(Table1[[#This Row],[AwayTeam]],Standings!$A$2:$A$33,0),3)=INDEX(Standings!$A$2:$C$33,MATCH(Table1[[#This Row],[HomeTeam]],Standings!$A$2:$A$33,0),3),1,0) -> 0 | AL6: =IF(Table1[[#This Row],[InterConf]]=1,IF(Table1[[#This Row],[InterDiv]]=0, 1, 0), 0) -> 1 | AM6: =IF(INDEX(Standings!$A$2:$C$33,MATCH(Table1[[#This Row],[AwayTeam]],Standings!$A$2:$A$33,0),2)<>INDEX(Standings!$A$2:$C$33,MATCH(Table1[[#This Row],[HomeTeam]],Standings!$A$2:$A$33,0),2),1,0) -> 0 | AN6: =INDEX(Table2[AWAY_RECORD], MATCH(Table1[[#This Row],[AwayTeam]],Table2[Team], 0), 0) -> 1-0-1 | AO6: =INDEX(Records!$B$2:$AG$33, MATCH(Table1[[#This Row],[AwayTeam]],Records!$A$2:$A$33, 0), MATCH(Table1[[#This Row],[HomeTeam]],Records!$A$2:$A$33, 0)) -> 1-0-0 | AP6: =INDEX(Table2[HOME_RECORD], MATCH(Table1[[#This Row],[HomeTeam]],Table2[Team], 0), 0) -> 0-0-1 | AQ6: =INDEX(Records!$B$2:$AG$33, MATCH(Table1[[#This Row],[HomeTeam]],Records!$A$2:$A$33, 0), MATCH(Table1[[#This Row],[AwayTeam]],Records!$A$2:$A$33, 0)) -> 0-0-1
C7: =IF(WEEKDAY(Table1[[#This Row],[GameDate]])=1,"SUN",IF(WEEKDAY(Table1[[#This Row],[GameDate]])=2,"MON",IF(WEEKDAY(Table1[[#This Row],[GameDate]])=3,"TUE",IF(WEEKDAY(Table1[[#This Row],[GameDate]])=4,"WED",IF(WEEKDAY(Table1[[#This Row],[GameDate]])=5,"THU",IF(WEEKDAY(Table1[[#This Row],[GameDate]])=6,"FRI", "SAT")))))) -> WED | D7: 2026-09-30 | E7: 20:30 | F7: 2026020006 | G7: PIT | H7: PHI | I7: 5 | J7: 4 | K7: OT | L7: =IF(OR(Table1[[#This Row],[PredictedAwayScore]]=Table1[[#This Row],[PredictedHomeScore]],AND(ISBLANK(Table1[[#This Row],[PredictedAwayScore]]),ISBLANK(Table1[[#This Row],[PredictedHomeScore]]))),"",IF(Table1[[#This Row],[PredictedAwayScore]]>Table1[[#This Row],[PredictedHomeScore]],Table1[[#This Row],[AwayTeam]],Table1[[#This Row],[HomeTeam]])) -> PIT | M7: 4 | N7: 5 | O7: OT | P7: =IF(OR(Table1[[#This Row],[ActualAwayScore]]=Table1[[#This Row],[ActualHomeScore]],AND(ISBLANK(Table1[[#This Row],[ActualAwayScore]]),ISBLANK(Table1[[#This Row],[ActualHomeScore]]))),"",IF(Table1[[#This Row],[ActualAwayScore]]>Table1[[#This Row],[ActualHomeScore]],Table1[[#This Row],[AwayTeam]], Table1[[#This Row],[HomeTeam]])) -> PHI | T7: =IF(Table1[[#This Row],[ActualWinner]]="", "", IF(Table1[[#This Row],[AwayTeam]]=Table1[[#This Row],[ActualWinner]],Table1[[#This Row],[HomeTeam]],Table1[[#This Row],[AwayTeam]])) -> PIT | U7: =Table1[[#This Row],[ActualAwayScore]]-Table1[[#This Row],[PredictedAwayScore]] -> -1 | V7: =Table1[[#This Row],[ActualHomeScore]]-Table1[[#This Row],[PredictedHomeScore]] -> 1 | W7: =(0.8*IF(Table1[[#This Row],[CorrectWinnerPrediction]]=1, 1, 0))+(0.1*IF(Table1[[#This Row],[CorrectAwayScorePrediction]]=1, 1, 0))+(0.1*IF(Table1[[#This Row],[CorrectHomeScorePrediction]]=1, 1, 0)) -> 0 | X7: =(0.8*IF(Table1[[#This Row],[CorrectWinnerPrediction]]=1, 1, 0))+(0.1*IF(Table1[[#This Row],[CorrectAwayScorePrediction]]=1, 1, 0))+(0.1*IF(Table1[[#This Row],[CorrectHomeScorePrediction]]=1, 1, 0)) + (0.8 * IF(OR(Table1[[#This Row],[PredictedResult]]="REG",Table1[[#This Row],[CorrectWinnerPrediction]]=1), 0, IF(Table1[[#This Row],[ActualResult]]="OT", 0.85, IF(Table1[[#This Row],[ActualResult]]="SO", 0.95, 0)))) -> 0.68 | Z7: =SUMIF(Table1[GameDate], Table1[[#This Row],[GameDate]], Table1[AwayGameGoalDiff]) -> -3 | AA7: =SUMIF(Table1[GameDate], Table1[[#This Row],[GameDate]], Table1[HomeGameGoalDiff]) -> -1 | AB7: =IF(ISBLANK(Table1[[#This Row],[ActualResult]]), 0, 1) -> 1 | AC7: =IF(ISBLANK(Table1[[#This Row],[ActualResult]]), 0, IF(Table1[[#This Row],[ActualWinner]]=Table1[[#This Row],[PredictedWinner]], 1, 0)) -> 0 | AD7: =IF(Table1[[#This Row],[ActualAwayScore]]>Table1[[#This Row],[PredictedAwayScore]], 0, IF(ISBLANK(Table1[[#This Row],[ActualResult]]), 0, IF(Table1[[#This Row],[ActualAwayScore]]=Table1[[#This Row],[PredictedAwayScore]], 1,0))) -> 0 | AE7: =IF(Table1[[#This Row],[ActualHomeScore]]>Table1[[#This Row],[PredictedHomeScore]], 0, IF(ISBLANK(Table1[[#This Row],[ActualResult]]), 0, IF(Table1[[#This Row],[ActualHomeScore]]=Table1[[#This Row],[PredictedHomeScore]], 1, 0))) -> 0 | AF7: =IF(AND(Table1[[#This Row],[GameIsOver]]=1,Table1[[#This Row],[ActualAwayScore]]=0), 1,0) -> 0 | AG7: =IF(AND(Table1[[#This Row],[GameIsOver]]=1,Table1[[#This Row],[ActualHomeScore]]=0), 1,0) -> 0 | AH7: =IF(Table1[[#This Row],[GameIsOver]]=0,0,IF(Table1[[#This Row],[ActualWinner]]=Table1[[#This Row],[AwayTeam]], 1, 0)) -> 0 | AI7: =IF(Table1[[#This Row],[GameIsOver]]=0,0,IF(Table1[[#This Row],[ActualWinner]]=Table1[[#This Row],[HomeTeam]], 1, 0)) -> 1 | AJ7: =IF(INDEX(Standings!$A$2:$C$33,MATCH(Table1[[#This Row],[AwayTeam]],Standings!$A$2:$A$33,0),2)=INDEX(Standings!$A$2:$C$33,MATCH(Table1[[#This Row],[HomeTeam]],Standings!$A$2:$A$33,0),2),1,0) -> 1 | AK7: =IF(INDEX(Standings!$A$2:$C$33,MATCH(Table1[[#This Row],[AwayTeam]],Standings!$A$2:$A$33,0),3)=INDEX(Standings!$A$2:$C$33,MATCH(Table1[[#This Row],[HomeTeam]],Standings!$A$2:$A$33,0),3),1,0) -> 1 | AL7: =IF(Table1[[#This Row],[InterConf]]=1,IF(Table1[[#This Row],[InterDiv]]=0, 1, 0), 0) -> 0 | AM7: =IF(INDEX(Standings!$A$2:$C$33,MATCH(Table1[[#This Row],[AwayTeam]],Standings!$A$2:$A$33,0),2)<>INDEX(Standings!$A$2:$C$33,MATCH(Table1[[#This Row],[HomeTeam]],Standings!$A$2:$A$33,0),2),1,0) -> 0 | AN7: =INDEX(Table2[AWAY_RECORD], MATCH(Table1[[#This Row],[AwayTeam]],Table2[Team], 0), 0) -> 0-0-1 | AO7: =INDEX(Records!$B$2:$AG$33, MATCH(Table1[[#This Row],[AwayTeam]],Records!$A$2:$A$33, 0), MATCH(Table1[[#This Row],[HomeTeam]],Records!$A$2:$A$33, 0)) -> 0-0-1 | AP7: =INDEX(Table2[HOME_RECORD], MATCH(Table1[[#This Row],[HomeTeam]],Table2[Team], 0), 0) -> 1-0-0 | AQ7: =INDEX(Records!$B$2:$AG$33, MATCH(Table1[[#This Row],[HomeTeam]],Records!$A$2:$A$33, 0), MATCH(Table1[[#This Row],[AwayTeam]],Records!$A$2:$A$33, 0)) -> 1-0-0
C8: =IF(WEEKDAY(Table1[[#This Row],[GameDate]])=1,"SUN",IF(WEEKDAY(Table1[[#This Row],[GameDate]])=2,"MON",IF(WEEKDAY(Table1[[#This Row],[GameDate]])=3,"TUE",IF(WEEKDAY(Table1[[#This Row],[GameDate]])=4,"WED",IF(WEEKDAY(Table1[[#This Row],[GameDate]])=5,"THU",IF(WEEKDAY(Table1[[#This Row],[GameDate]])=6,"FRI", "SAT")))))) -> WED | D8: 2026-09-30 | E8: 20:30 | F8: 2026020008 | G8: NYI | H8: TOR | I8: 2 | J8: 1 | K8: REG | L8: =IF(OR(Table1[[#This Row],[PredictedAwayScore]]=Table1[[#This Row],[PredictedHomeScore]],AND(ISBLANK(Table1[[#This Row],[PredictedAwayScore]]),ISBLANK(Table1[[#This Row],[PredictedHomeScore]]))),"",IF(Table1[[#This Row],[PredictedAwayScore]]>Table1[[#This Row],[PredictedHomeScore]],Table1[[#This Row],[AwayTeam]],Table1[[#This Row],[HomeTeam]])) -> NYI | M8: 4 | N8: 3 | O8: REG | P8: =IF(OR(Table1[[#This Row],[ActualAwayScore]]=Table1[[#This Row],[ActualHomeScore]],AND(ISBLANK(Table1[[#This Row],[ActualAwayScore]]),ISBLANK(Table1[[#This Row],[ActualHomeScore]]))),"",IF(Table1[[#This Row],[ActualAwayScore]]>Table1[[#This Row],[ActualHomeScore]],Table1[[#This Row],[AwayTeam]], Table1[[#This Row],[HomeTeam]])) -> NYI | T8: =IF(Table1[[#This Row],[ActualWinner]]="", "", IF(Table1[[#This Row],[AwayTeam]]=Table1[[#This Row],[ActualWinner]],Table1[[#This Row],[HomeTeam]],Table1[[#This Row],[AwayTeam]])) -> TOR | U8: =Table1[[#This Row],[ActualAwayScore]]-Table1[[#This Row],[PredictedAwayScore]] -> 2 | V8: =Table1[[#This Row],[ActualHomeScore]]-Table1[[#This Row],[PredictedHomeScore]] -> 2 | W8: =(0.8*IF(Table1[[#This Row],[CorrectWinnerPrediction]]=1, 1, 0))+(0.1*IF(Table1[[#This Row],[CorrectAwayScorePrediction]]=1, 1, 0))+(0.1*IF(Table1[[#This Row],[CorrectHomeScorePrediction]]=1, 1, 0)) -> 0.8 | X8: =(0.8*IF(Table1[[#This Row],[CorrectWinnerPrediction]]=1, 1, 0))+(0.1*IF(Table1[[#This Row],[CorrectAwayScorePrediction]]=1, 1, 0))+(0.1*IF(Table1[[#This Row],[CorrectHomeScorePrediction]]=1, 1, 0)) + (0.8 * IF(OR(Table1[[#This Row],[PredictedResult]]="REG",Table1[[#This Row],[CorrectWinnerPrediction]]=1), 0, IF(Table1[[#This Row],[ActualResult]]="OT", 0.85, IF(Table1[[#This Row],[ActualResult]]="SO", 0.95, 0)))) -> 0.8 | Z8: =SUMIF(Table1[GameDate], Table1[[#This Row],[GameDate]], Table1[AwayGameGoalDiff]) -> -3 | AA8: =SUMIF(Table1[GameDate], Table1[[#This Row],[GameDate]], Table1[HomeGameGoalDiff]) -> -1 | AB8: =IF(ISBLANK(Table1[[#This Row],[ActualResult]]), 0, 1) -> 1 | AC8: =IF(ISBLANK(Table1[[#This Row],[ActualResult]]), 0, IF(Table1[[#This Row],[ActualWinner]]=Table1[[#This Row],[PredictedWinner]], 1, 0)) -> 1 | AD8: =IF(Table1[[#This Row],[ActualAwayScore]]>Table1[[#This Row],[PredictedAwayScore]], 0, IF(ISBLANK(Table1[[#This Row],[ActualResult]]), 0, IF(Table1[[#This Row],[ActualAwayScore]]=Table1[[#This Row],[PredictedAwayScore]], 1,0))) -> 0 | AE8: =IF(Table1[[#This Row],[ActualHomeScore]]>Table1[[#This Row],[PredictedHomeScore]], 0, IF(ISBLANK(Table1[[#This Row],[ActualResult]]), 0, IF(Table1[[#This Row],[ActualHomeScore]]=Table1[[#This Row],[PredictedHomeScore]], 1, 0))) -> 0 | AF8: =IF(AND(Table1[[#This Row],[GameIsOver]]=1,Table1[[#This Row],[ActualAwayScore]]=0), 1,0) -> 0 | AG8: =IF(AND(Table1[[#This Row],[GameIsOver]]=1,Table1[[#This Row],[ActualHomeScore]]=0), 1,0) -> 0 | AH8: =IF(Table1[[#This Row],[GameIsOver]]=0,0,IF(Table1[[#This Row],[ActualWinner]]=Table1[[#This Row],[AwayTeam]], 1, 0)) -> 1 | AI8: =IF(Table1[[#This Row],[GameIsOver]]=0,0,IF(Table1[[#This Row],[ActualWinner]]=Table1[[#This Row],[HomeTeam]], 1, 0)) -> 0 | AJ8: =IF(INDEX(Standings!$A$2:$C$33,MATCH(Table1[[#This Row],[AwayTeam]],Standings!$A$2:$A$33,0),2)=INDEX(Standings!$A$2:$C$33,MATCH(Table1[[#This Row],[HomeTeam]],Standings!$A$2:$A$33,0),2),1,0) -> 1 | AK8: =IF(INDEX(Standings!$A$2:$C$33,MATCH(Table1[[#This Row],[AwayTeam]],Standings!$A$2:$A$33,0),3)=INDEX(Standings!$A$2:$C$33,MATCH(Table1[[#This Row],[HomeTeam]],Standings!$A$2:$A$33,0),3),1,0) -> 0 | AL8: =IF(Table1[[#This Row],[InterConf]]=1,IF(Table1[[#This Row],[InterDiv]]=0, 1, 0), 0) -> 1 | AM8: =IF(INDEX(Standings!$A$2:$C$33,MATCH(Table1[[#This Row],[AwayTeam]],Standings!$A$2:$A$33,0),2)<>INDEX(Standings!$A$2:$C$33,MATCH(Table1[[#This Row],[HomeTeam]],Standings!$A$2:$A$33,0),2),1,0) -> 0 | AN8: =INDEX(Table2[AWAY_RECORD], MATCH(Table1[[#This Row],[AwayTeam]],Table2[Team], 0), 0) -> 1-0-0 | AO8: =INDEX(Records!$B$2:$AG$33, MATCH(Table1[[#This Row],[AwayTeam]],Records!$A$2:$A$33, 0), MATCH(Table1[[#This Row],[HomeTeam]],Records!$A$2:$A$33, 0)) -> 1-0-0 | AP8: =INDEX(Table2[HOME_RECORD], MATCH(Table1[[#This Row],[HomeTeam]],Table2[Team], 0), 0) -> 0-2-0 | AQ8: =INDEX(Records!$B$2:$AG$33, MATCH(Table1[[#This Row],[HomeTeam]],Records!$A$2:$A$33, 0), MATCH(Table1[[#This Row],[AwayTeam]],Records!$A$2:$A$33, 0)) -> 0-1-0
C9: =IF(WEEKDAY(Table1[[#This Row],[GameDate]])=1,"SUN",IF(WEEKDAY(Table1[[#This Row],[GameDate]])=2,"MON",IF(WEEKDAY(Table1[[#This Row],[GameDate]])=3,"TUE",IF(WEEKDAY(Table1[[#This Row],[GameDate]])=4,"WED",IF(WEEKDAY(Table1[[#This Row],[GameDate]])=5,"THU",IF(WEEKDAY(Table1[[#This Row],[GameDate]])=6,"FRI", "SAT")))))) -> WED | D9: 2026-09-30 | E9: 23:00 | F9: 2026020007 | G9: LAK | H9: COL | I9: 6 | J9: 5 | K9: REG | L9: =IF(OR(Table1[[#This Row],[PredictedAwayScore]]=Table1[[#This Row],[PredictedHomeScore]],AND(ISBLANK(Table1[[#This Row],[PredictedAwayScore]]),ISBLANK(Table1[[#This Row],[PredictedHomeScore]]))),"",IF(Table1[[#This Row],[PredictedAwayScore]]>Table1[[#This Row],[PredictedHomeScore]],Table1[[#This Row],[AwayTeam]],Table1[[#This Row],[HomeTeam]])) -> LAK | M9: 2 | N9: 1 | O9: OT | P9: =IF(OR(Table1[[#This Row],[ActualAwayScore]]=Table1[[#This Row],[ActualHomeScore]],AND(ISBLANK(Table1[[#This Row],[ActualAwayScore]]),ISBLANK(Table1[[#This Row],[ActualHomeScore]]))),"",IF(Table1[[#This Row],[ActualAwayScore]]>Table1[[#This Row],[ActualHomeScore]],Table1[[#This Row],[AwayTeam]], Table1[[#This Row],[HomeTeam]])) -> LAK | T9: =IF(Table1[[#This Row],[ActualWinner]]="", "", IF(Table1[[#This Row],[AwayTeam]]=Table1[[#This Row],[ActualWinner]],Table1[[#This Row],[HomeTeam]],Table1[[#This Row],[AwayTeam]])) -> COL | U9: =Table1[[#This Row],[ActualAwayScore]]-Table1[[#This Row],[PredictedAwayScore]] -> -4 | V9: =Table1[[#This Row],[ActualHomeScore]]-Table1[[#This Row],[PredictedHomeScore]] -> -4 | W9: =(0.8*IF(Table1[[#This Row],[CorrectWinnerPrediction]]=1, 1, 0))+(0.1*IF(Table1[[#This Row],[CorrectAwayScorePrediction]]=1, 1, 0))+(0.1*IF(Table1[[#This Row],[CorrectHomeScorePrediction]]=1, 1, 0)) -> 0.8 | X9: =(0.8*IF(Table1[[#This Row],[CorrectWinnerPrediction]]=1, 1, 0))+(0.1*IF(Table1[[#This Row],[CorrectAwayScorePrediction]]=1, 1, 0))+(0.1*IF(Table1[[#This Row],[CorrectHomeScorePrediction]]=1, 1, 0)) + (0.8 * IF(OR(Table1[[#This Row],[PredictedResult]]="REG",Table1[[#This Row],[CorrectWinnerPrediction]]=1), 0, IF(Table1[[#This Row],[ActualResult]]="OT", 0.85, IF(Table1[[#This Row],[ActualResult]]="SO", 0.95, 0)))) -> 0.8 | Z9: =SUMIF(Table1[GameDate], Table1[[#This Row],[GameDate]], Table1[AwayGameGoalDiff]) -> -3 | AA9: =SUMIF(Table1[GameDate], Table1[[#This Row],[GameDate]], Table1[HomeGameGoalDiff]) -> -1 | AB9: =IF(ISBLANK(Table1[[#This Row],[ActualResult]]), 0, 1) -> 1 | AC9: =IF(ISBLANK(Table1[[#This Row],[ActualResult]]), 0, IF(Table1[[#This Row],[ActualWinner]]=Table1[[#This Row],[PredictedWinner]], 1, 0)) -> 1 | AD9: =IF(Table1[[#This Row],[ActualAwayScore]]>Table1[[#This Row],[PredictedAwayScore]], 0, IF(ISBLANK(Table1[[#This Row],[ActualResult]]), 0, IF(Table1[[#This Row],[ActualAwayScore]]=Table1[[#This Row],[PredictedAwayScore]], 1,0))) -> 0 | AE9: =IF(Table1[[#This Row],[ActualHomeScore]]>Table1[[#This Row],[PredictedHomeScore]], 0, IF(ISBLANK(Table1[[#This Row],[ActualResult]]), 0, IF(Table1[[#This Row],[ActualHomeScore]]=Table1[[#This Row],[PredictedHomeScore]], 1, 0))) -> 0 | AF9: =IF(AND(Table1[[#This Row],[GameIsOver]]=1,Table1[[#This Row],[ActualAwayScore]]=0), 1,0) -> 0 | AG9: =IF(AND(Table1[[#This Row],[GameIsOver]]=1,Table1[[#This Row],[ActualHomeScore]]=0), 1,0) -> 0 | AH9: =IF(Table1[[#This Row],[GameIsOver]]=0,0,IF(Table1[[#This Row],[ActualWinner]]=Table1[[#This Row],[AwayTeam]], 1, 0)) -> 1 | AI9: =IF(Table1[[#This Row],[GameIsOver]]=0,0,IF(Table1[[#This Row],[ActualWinner]]=Table1[[#This Row],[HomeTeam]], 1, 0)) -> 0 | AJ9: =IF(INDEX(Standings!$A$2:$C$33,MATCH(Table1[[#This Row],[AwayTeam]],Standings!$A$2:$A$33,0),2)=INDEX(Standings!$A$2:$C$33,MATCH(Table1[[#This Row],[HomeTeam]],Standings!$A$2:$A$33,0),2),1,0) -> 1 | AK9: =IF(INDEX(Standings!$A$2:$C$33,MATCH(Table1[[#This Row],[AwayTeam]],Standings!$A$2:$A$33,0),3)=INDEX(Standings!$A$2:$C$33,MATCH(Table1[[#This Row],[HomeTeam]],Standings!$A$2:$A$33,0),3),1,0) -> 0 | AL9: =IF(Table1[[#This Row],[InterConf]]=1,IF(Table1[[#This Row],[InterDiv]]=0, 1, 0), 0) -> 1 | AM9: =IF(INDEX(Standings!$A$2:$C$33,MATCH(Table1[[#This Row],[AwayTeam]],Standings!$A$2:$A$33,0),2)<>INDEX(Standings!$A$2:$C$33,MATCH(Table1[[#This Row],[HomeTeam]],Standings!$A$2:$A$33,0),2),1,0) -> 0 | AN9: =INDEX(Table2[AWAY_RECORD], MATCH(Table1[[#This Row],[AwayTeam]],Table2[Team], 0), 0) -> 1-0-0 | AO9: =INDEX(Records!$B$2:$AG$33, MATCH(Table1[[#This Row],[AwayTeam]],Records!$A$2:$A$33, 0), MATCH(Table1[[#This Row],[HomeTeam]],Records!$A$2:$A$33, 0)) -> 1-0-0 | AP9: =INDEX(Table2[HOME_RECORD], MATCH(Table1[[#This Row],[HomeTeam]],Table2[Team], 0), 0) -> 0-0-1 | AQ9: =INDEX(Records!$B$2:$AG$33, MATCH(Table1[[#This Row],[HomeTeam]],Records!$A$2:$A$33, 0), MATCH(Table1[[#This Row],[AwayTeam]],Records!$A$2:$A$33, 0)) -> 0-0-1
C10: =IF(WEEKDAY(Table1[[#This Row],[GameDate]])=1,"SUN",IF(WEEKDAY(Table1[[#This Row],[GameDate]])=2,"MON",IF(WEEKDAY(Table1[[#This Row],[GameDate]])=3,"TUE",IF(WEEKDAY(Table1[[#This Row],[GameDate]])=4,"WED",IF(WEEKDAY(Table1[[#This Row],[GameDate]])=5,"THU",IF(WEEKDAY(Table1[[#This Row],[GameDate]])=6,"FRI", "SAT")))))) -> THU | D10: 2026-10-01 | E10: 20:00 | F10: 2026020009 | G10: PHI | H10: NJD | I10: 3 | J10: 6 | K10: REG | L10: =IF(OR(Table1[[#This Row],[PredictedAwayScore]]=Table1[[#This Row],[PredictedHomeScore]],AND(ISBLANK(Table1[[#This Row],[PredictedAwayScore]]),ISBLANK(Table1[[#This Row],[PredictedHomeScore]]))),"",IF(Table1[[#This Row],[PredictedAwayScore]]>Table1[[#This Row],[PredictedHomeScore]],Table1[[#This Row],[AwayTeam]],Table1[[#This Row],[HomeTeam]])) -> NJD | M10: 3 | N10: 5 | O10: REG | P10: =IF(OR(Table1[[#This Row],[ActualAwayScore]]=Table1[[#This Row],[ActualHomeScore]],AND(ISBLANK(Table1[[#This Row],[ActualAwayScore]]),ISBLANK(Table1[[#This Row],[ActualHomeScore]]))),"",IF(Table1[[#This Row],[ActualAwayScore]]>Table1[[#This Row],[ActualHomeScore]],Table1[[#This Row],[AwayTeam]], Table1[[#This Row],[HomeTeam]])) -> NJD | T10: =IF(Table1[[#This Row],[ActualWinner]]="", "", IF(Table1[[#This Row],[AwayTeam]]=Table1[[#This Row],[ActualWinner]],Table1[[#This Row],[HomeTeam]],Table1[[#This Row],[AwayTeam]])) -> PHI | U10: =Table1[[#This Row],[ActualAwayScore]]-Table1[[#This Row],[PredictedAwayScore]] -> 0 | V10: =Table1[[#This Row],[ActualHomeScore]]-Table1[[#This Row],[PredictedHomeScore]] -> -1 | W10: =(0.8*IF(Table1[[#This Row],[CorrectWinnerPrediction]]=1, 1, 0))+(0.1*IF(Table1[[#This Row],[CorrectAwayScorePrediction]]=1, 1, 0))+(0.1*IF(Table1[[#This Row],[CorrectHomeScorePrediction]]=1, 1, 0)) -> 0.9 | X10: =(0.8*IF(Table1[[#This Row],[CorrectWinnerPrediction]]=1, 1, 0))+(0.1*IF(Table1[[#This Row],[CorrectAwayScorePrediction]]=1, 1, 0))+(0.1*IF(Table1[[#This Row],[CorrectHomeScorePrediction]]=1, 1, 0)) + (0.8 * IF(OR(Table1[[#This Row],[PredictedResult]]="REG",Table1[[#This Row],[CorrectWinnerPrediction]]=1), 0, IF(Table1[[#This Row],[ActualResult]]="OT", 0.85, IF(Table1[[#This Row],[ActualResult]]="SO", 0.95, 0)))) -> 0.9 | Z10: =SUMIF(Table1[GameDate], Table1[[#This Row],[GameDate]], Table1[AwayGameGoalDiff]) -> 3 | AA10: =SUMIF(Table1[GameDate], Table1[[#This Row],[GameDate]], Table1[HomeGameGoalDiff]) -> -4 | AB10: =IF(ISBLANK(Table1[[#This Row],[ActualResult]]), 0, 1) -> 1 | AC10: =IF(ISBLANK(Table1[[#This Row],[ActualResult]]), 0, IF(Table1[[#This Row],[ActualWinner]]=Table1[[#This Row],[PredictedWinner]], 1, 0)) -> 1 | AD10: =IF(Table1[[#This Row],[ActualAwayScore]]>Table1[[#This Row],[PredictedAwayScore]], 0, IF(ISBLANK(Table1[[#This Row],[ActualResult]]), 0, IF(Table1[[#This Row],[ActualAwayScore]]=Table1[[#This Row],[PredictedAwayScore]], 1,0))) -> 1 | AE10: =IF(Table1[[#This Row],[ActualHomeScore]]>Table1[[#This Row],[PredictedHomeScore]], 0, IF(ISBLANK(Table1[[#This Row],[ActualResult]]), 0, IF(Table1[[#This Row],[ActualHomeScore]]=Table1[[#This Row],[PredictedHomeScore]], 1, 0))) -> 0 | AF10: =IF(AND(Table1[[#This Row],[GameIsOver]]=1,Table1[[#This Row],[ActualAwayScore]]=0), 1,0) -> 0 | AG10: =IF(AND(Table1[[#This Row],[GameIsOver]]=1,Table1[[#This Row],[ActualHomeScore]]=0), 1,0) -> 0 | AH10: =IF(Table1[[#This Row],[GameIsOver]]=0,0,IF(Table1[[#This Row],[ActualWinner]]=Table1[[#This Row],[AwayTeam]], 1, 0)) -> 0 | AI10: =IF(Table1[[#This Row],[GameIsOver]]=0,0,IF(Table1[[#This Row],[ActualWinner]]=Table1[[#This Row],[HomeTeam]], 1, 0)) -> 1 | AJ10: =IF(INDEX(Standings!$A$2:$C$33,MATCH(Table1[[#This Row],[AwayTeam]],Standings!$A$2:$A$33,0),2)=INDEX(Standings!$A$2:$C$33,MATCH(Table1[[#This Row],[HomeTeam]],Standings!$A$2:$A$33,0),2),1,0) -> 1 | AK10: =IF(INDEX(Standings!$A$2:$C$33,MATCH(Table1[[#This Row],[AwayTeam]],Standings!$A$2:$A$33,0),3)=INDEX(Standings!$A$2:$C$33,MATCH(Table1[[#This Row],[HomeTeam]],Standings!$A$2:$A$33,0),3),1,0) -> 1 | AL10: =IF(Table1[[#This Row],[InterConf]]=1,IF(Table1[[#This Row],[InterDiv]]=0, 1, 0), 0) -> 0 | AM10: =IF(INDEX(Standings!$A$2:$C$33,MATCH(Table1[[#This Row],[AwayTeam]],Standings!$A$2:$A$33,0),2)<>INDEX(Standings!$A$2:$C$33,MATCH(Table1[[#This Row],[HomeTeam]],Standings!$A$2:$A$33,0),2),1,0) -> 0 | AN10: =INDEX(Table2[AWAY_RECORD], MATCH(Table1[[#This Row],[AwayTeam]],Table2[Team], 0), 0) -> 0-1-0 | AO10: =INDEX(Records!$B$2:$AG$33, MATCH(Table1[[#This Row],[AwayTeam]],Records!$A$2:$A$33, 0), MATCH(Table1[[#This Row],[HomeTeam]],Records!$A$2:$A$33, 0)) -> 0-1-0 | AP10: =INDEX(Table2[HOME_RECORD], MATCH(Table1[[#This Row],[HomeTeam]],Table2[Team], 0), 0) -> 1-0-0 | AQ10: =INDEX(Records!$B$2:$AG$33, MATCH(Table1[[#This Row],[HomeTeam]],Records!$A$2:$A$33, 0), MATCH(Table1[[#This Row],[AwayTeam]],Records!$A$2:$A$33, 0)) -> 1-0-0
C11: =IF(WEEKDAY(Table1[[#This Row],[GameDate]])=1,"SUN",IF(WEEKDAY(Table1[[#This Row],[GameDate]])=2,"MON",IF(WEEKDAY(Table1[[#This Row],[GameDate]])=3,"TUE",IF(WEEKDAY(Table1[[#This Row],[GameDate]])=4,"WED",IF(WEEKDAY(Table1[[#This Row],[GameDate]])=5,"THU",IF(WEEKDAY(Table1[[#This Row],[GameDate]])=6,"FRI", "SAT")))))) -> THU | D11: 2026-10-01 | E11: 20:00 | F11: 2026020010 | G11: TBL | H11: NYR | I11: 3 | J11: 4 | K11: OT | L11: =IF(OR(Table1[[#This Row],[PredictedAwayScore]]=Table1[[#This Row],[PredictedHomeScore]],AND(ISBLANK(Table1[[#This Row],[PredictedAwayScore]]),ISBLANK(Table1[[#This Row],[PredictedHomeScore]]))),"",IF(Table1[[#This Row],[PredictedAwayScore]]>Table1[[#This Row],[PredictedHomeScore]],Table1[[#This Row],[AwayTeam]],Table1[[#This Row],[HomeTeam]])) -> NYR | M11: 3 | N11: 4 | O11: REG | P11: =IF(OR(Table1[[#This Row],[ActualAwayScore]]=Table1[[#This Row],[ActualHomeScore]],AND(ISBLANK(Table1[[#This Row],[ActualAwayScore]]),ISBLANK(Table1[[#This Row],[ActualHomeScore]]))),"",IF(Table1[[#This Row],[ActualAwayScore]]>Table1[[#This Row],[ActualHomeScore]],Table1[[#This Row],[AwayTeam]], Table1[[#This Row],[HomeTeam]])) -> NYR | T11: =IF(Table1[[#This Row],[ActualWinner]]="", "", IF(Table1[[#This Row],[AwayTeam]]=Table1[[#This Row],[ActualWinner]],Table1[[#This Row],[HomeTeam]],Table1[[#This Row],[AwayTeam]])) -> TBL | U11: =Table1[[#This Row],[ActualAwayScore]]-Table1[[#This Row],[PredictedAwayScore]] -> 0 | V11: =Table1[[#This Row],[ActualHomeScore]]-Table1[[#This Row],[PredictedHomeScore]] -> 0 | W11: =(0.8*IF(Table1[[#This Row],[CorrectWinnerPrediction]]=1, 1, 0))+(0.1*IF(Table1[[#This Row],[CorrectAwayScorePrediction]]=1, 1, 0))+(0.1*IF(Table1[[#This Row],[CorrectHomeScorePrediction]]=1, 1, 0)) -> 1 | X11: =(0.8*IF(Table1[[#This Row],[CorrectWinnerPrediction]]=1, 1, 0))+(0.1*IF(Table1[[#This Row],[CorrectAwayScorePrediction]]=1, 1, 0))+(0.1*IF(Table1[[#This Row],[CorrectHomeScorePrediction]]=1, 1, 0)) + (0.8 * IF(OR(Table1[[#This Row],[PredictedResult]]="REG",Table1[[#This Row],[CorrectWinnerPrediction]]=1), 0, IF(Table1[[#This Row],[ActualResult]]="OT", 0.85, IF(Table1[[#This Row],[ActualResult]]="SO", 0.95, 0)))) -> 1 | Z11: =SUMIF(Table1[GameDate], Table1[[#This Row],[GameDate]], Table1[AwayGameGoalDiff]) -> 3 | AA11: =SUMIF(Table1[GameDate], Table1[[#This Row],[GameDate]], Table1[HomeGameGoalDiff]) -> -4 | AB11: =IF(ISBLANK(Table1[[#This Row],[ActualResult]]), 0, 1) -> 1 | AC11: =IF(ISBLANK(Table1[[#This Row],[ActualResult]]), 0, IF(Table1[[#This Row],[ActualWinner]]=Table1[[#This Row],[PredictedWinner]], 1, 0)) -> 1 | AD11: =IF(Table1[[#This Row],[ActualAwayScore]]>Table1[[#This Row],[PredictedAwayScore]], 0, IF(ISBLANK(Table1[[#This Row],[ActualResult]]), 0, IF(Table1[[#This Row],[ActualAwayScore]]=Table1[[#This Row],[PredictedAwayScore]], 1,0))) -> 1 | AE11: =IF(Table1[[#This Row],[ActualHomeScore]]>Table1[[#This Row],[PredictedHomeScore]], 0, IF(ISBLANK(Table1[[#This Row],[ActualResult]]), 0, IF(Table1[[#This Row],[ActualHomeScore]]=Table1[[#This Row],[PredictedHomeScore]], 1, 0))) -> 1 | AF11: =IF(AND(Table1[[#This Row],[GameIsOver]]=1,Table1[[#This Row],[ActualAwayScore]]=0), 1,0) -> 0 | AG11: =IF(AND(Table1[[#This Row],[GameIsOver]]=1,Table1[[#This Row],[ActualHomeScore]]=0), 1,0) -> 0 | AH11: =IF(Table1[[#This Row],[GameIsOver]]=0,0,IF(Table1[[#This Row],[ActualWinner]]=Table1[[#This Row],[AwayTeam]], 1, 0)) -> 0 | AI11: =IF(Table1[[#This Row],[GameIsOver]]=0,0,IF(Table1[[#This Row],[ActualWinner]]=Table1[[#This Row],[HomeTeam]], 1, 0)) -> 1 | AJ11: =IF(INDEX(Standings!$A$2:$C$33,MATCH(Table1[[#This Row],[AwayTeam]],Standings!$A$2:$A$33,0),2)=INDEX(Standings!$A$2:$C$33,MATCH(Table1[[#This Row],[HomeTeam]],Standings!$A$2:$A$33,0),2),1,0) -> 1 | AK11: =IF(INDEX(Standings!$A$2:$C$33,MATCH(Table1[[#This Row],[AwayTeam]],Standings!$A$2:$A$33,0),3)=INDEX(Standings!$A$2:$C$33,MATCH(Table1[[#This Row],[HomeTeam]],Standings!$A$2:$A$33,0),3),1,0) -> 0 | AL11: =IF(Table1[[#This Row],[InterConf]]=1,IF(Table1[[#This Row],[InterDiv]]=0, 1, 0), 0) -> 1 | AM11: =IF(INDEX(Standings!$A$2:$C$33,MATCH(Table1[[#This Row],[AwayTeam]],Standings!$A$2:$A$33,0),2)<>INDEX(Standings!$A$2:$C$33,MATCH(Table1[[#This Row],[HomeTeam]],Standings!$A$2:$A$33,0),2),1,0) -> 0 | AN11: =INDEX(Table2[AWAY_RECORD], MATCH(Table1[[#This Row],[AwayTeam]],Table2[Team], 0), 0) -> 0-1-0 | AO11: =INDEX(Records!$B$2:$AG$33, MATCH(Table1[[#This Row],[AwayTeam]],Records!$A$2:$A$33, 0), MATCH(Table1[[#This Row],[HomeTeam]],Records!$A$2:$A$33, 0)) -> 0-1-0 | AP11: =INDEX(Table2[HOME_RECORD], MATCH(Table1[[#This Row],[HomeTeam]],Table2[Team], 0), 0) -> 1-0-0 | AQ11: =INDEX(Records!$B$2:$AG$33, MATCH(Table1[[#This Row],[HomeTeam]],Records!$A$2:$A$33, 0), MATCH(Table1[[#This Row],[AwayTeam]],Records!$A$2:$A$33, 0)) -> 1-0-0
C12: =IF(WEEKDAY(Table1[[#This Row],[GameDate]])=1,"SUN",IF(WEEKDAY(Table1[[#This Row],[GameDate]])=2,"MON",IF(WEEKDAY(Table1[[#This Row],[GameDate]])=3,"TUE",IF(WEEKDAY(Table1[[#This Row],[GameDate]])=4,"WED",IF(WEEKDAY(Table1[[#This Row],[GameDate]])=5,"THU",IF(WEEKDAY(Table1[[#This Row],[GameDate]])=6,"FRI", "SAT")))))) -> THU | D12: 2026-10-01 | E12: 20:00 | F12: 2026020011 | G12: BUF | H12: CBJ | I12: 4 | J12: 5 | K12: REG | L12: =IF(OR(Table1[[#This Row],[PredictedAwayScore]]=Table1[[#This Row],[PredictedHomeScore]],AND(ISBLANK(Table1[[#This Row],[PredictedAwayScore]]),ISBLANK(Table1[[#This Row],[PredictedHomeScore]]))),"",IF(Table1[[#This Row],[PredictedAwayScore]]>Table1[[#This Row],[PredictedHomeScore]],Table1[[#This Row],[AwayTeam]],Table1[[#This Row],[HomeTeam]])) -> CBJ | M12: 2 | N12: 3 | O12: SO | P12: =IF(OR(Table1[[#This Row],[ActualAwayScore]]=Table1[[#This Row],[ActualHomeScore]],AND(ISBLANK(Table1[[#This Row],[ActualAwayScore]]),ISBLANK(Table1[[#This Row],[ActualHomeScore]]))),"",IF(Table1[[#This Row],[ActualAwayScore]]>Table1[[#This Row],[ActualHomeScore]],Table1[[#This Row],[AwayTeam]], Table1[[#This Row],[HomeTeam]])) -> CBJ | T12: =IF(Table1[[#This Row],[ActualWinner]]="", "", IF(Table1[[#This Row],[AwayTeam]]=Table1[[#This Row],[ActualWinner]],Table1[[#This Row],[HomeTeam]],Table1[[#This Row],[AwayTeam]])) -> BUF | U12: =Table1[[#This Row],[ActualAwayScore]]-Table1[[#This Row],[PredictedAwayScore]] -> -2 | V12: =Table1[[#This Row],[ActualHomeScore]]-Table1[[#This Row],[PredictedHomeScore]] -> -2 | W12: =(0.8*IF(Table1[[#This Row],[CorrectWinnerPrediction]]=1, 1, 0))+(0.1*IF(Table1[[#This Row],[CorrectAwayScorePrediction]]=1, 1, 0))+(0.1*IF(Table1[[#This Row],[CorrectHomeScorePrediction]]=1, 1, 0)) -> 0.8 | X12: =(0.8*IF(Table1[[#This Row],[CorrectWinnerPrediction]]=1, 1, 0))+(0.1*IF(Table1[[#This Row],[CorrectAwayScorePrediction]]=1, 1, 0))+(0.1*IF(Table1[[#This Row],[CorrectHomeScorePrediction]]=1, 1, 0)) + (0.8 * IF(OR(Table1[[#This Row],[PredictedResult]]="REG",Table1[[#This Row],[CorrectWinnerPrediction]]=1), 0, IF(Table1[[#This Row],[ActualResult]]="OT", 0.85, IF(Table1[[#This Row],[ActualResult]]="SO", 0.95, 0)))) -> 0.8 | Z12: =SUMIF(Table1[GameDate], Table1[[#This Row],[GameDate]], Table1[AwayGameGoalDiff]) -> 3 | AA12: =SUMIF(Table1[GameDate], Table1[[#This Row],[GameDate]], Table1[HomeGameGoalDiff]) -> -4 | AB12: =IF(ISBLANK(Table1[[#This Row],[ActualResult]]), 0, 1) -> 1 | AC12: =IF(ISBLANK(Table1[[#This Row],[ActualResult]]), 0, IF(Table1[[#This Row],[ActualWinner]]=Table1[[#This Row],[PredictedWinner]], 1, 0)) -> 1 | AD12: =IF(Table1[[#This Row],[ActualAwayScore]]>Table1[[#This Row],[PredictedAwayScore]], 0, IF(ISBLANK(Table1[[#This Row],[ActualResult]]), 0, IF(Table1[[#This Row],[ActualAwayScore]]=Table1[[#This Row],[PredictedAwayScore]], 1,0))) -> 0 | AE12: =IF(Table1[[#This Row],[ActualHomeScore]]>Table1[[#This Row],[PredictedHomeScore]], 0, IF(ISBLANK(Table1[[#This Row],[ActualResult]]), 0, IF(Table1[[#This Row],[ActualHomeScore]]=Table1[[#This Row],[PredictedHomeScore]], 1, 0))) -> 0 | AF12: =IF(AND(Table1[[#This Row],[GameIsOver]]=1,Table1[[#This Row],[ActualAwayScore]]=0), 1,0) -> 0 | AG12: =IF(AND(Table1[[#This Row],[GameIsOver]]=1,Table1[[#This Row],[ActualHomeScore]]=0), 1,0) -> 0 | AH12: =IF(Table1[[#This Row],[GameIsOver]]=0,0,IF(Table1[[#This Row],[ActualWinner]]=Table1[[#This Row],[AwayTeam]], 1, 0)) -> 0 | AI12: =IF(Table1[[#This Row],[GameIsOver]]=0,0,IF(Table1[[#This Row],[ActualWinner]]=Table1[[#This Row],[HomeTeam]], 1, 0)) -> 1 | AJ12: =IF(INDEX(Standings!$A$2:$C$33,MATCH(Table1[[#This Row],[AwayTeam]],Standings!$A$2:$A$33,0),2)=INDEX(Standings!$A$2:$C$33,MATCH(Table1[[#This Row],[HomeTeam]],Standings!$A$2:$A$33,0),2),1,0) -> 1 | AK12: =IF(INDEX(Standings!$A$2:$C$33,MATCH(Table1[[#This Row],[AwayTeam]],Standings!$A$2:$A$33,0),3)=INDEX(Standings!$A$2:$C$33,MATCH(Table1[[#This Row],[HomeTeam]],Standings!$A$2:$A$33,0),3),1,0) -> 0 | AL12: =IF(Table1[[#This Row],[InterConf]]=1,IF(Table1[[#This Row],[InterDiv]]=0, 1, 0), 0) -> 1 | AM12: =IF(INDEX(Standings!$A$2:$C$33,MATCH(Table1[[#This Row],[AwayTeam]],Standings!$A$2:$A$33,0),2)<>INDEX(Standings!$A$2:$C$33,MATCH(Table1[[#This Row],[HomeTeam]],Standings!$A$2:$A$33,0),2),1,0) -> 0 | AN12: =INDEX(Table2[AWAY_RECORD], MATCH(Table1[[#This Row],[AwayTeam]],Table2[Team], 0), 0) -> 0-0-1 | AO12: =INDEX(Records!$B$2:$AG$33, MATCH(Table1[[#This Row],[AwayTeam]],Records!$A$2:$A$33, 0), MATCH(Table1[[#This Row],[HomeTeam]],Records!$A$2:$A$33, 0)) -> 0-0-1 | AP12: =INDEX(Table2[HOME_RECORD], MATCH(Table1[[#This Row],[HomeTeam]],Table2[Team], 0), 0) -> 1-0-0 | AQ12: =INDEX(Records!$B$2:$AG$33, MATCH(Table1[[#This Row],[HomeTeam]],Records!$A$2:$A$33, 0), MATCH(Table1[[#This Row],[AwayTeam]],Records!$A$2:$A$33, 0)) -> 1-0-0
C13: =IF(WEEKDAY(Table1[[#This Row],[GameDate]])=1,"SUN",IF(WEEKDAY(Table1[[#This Row],[GameDate]])=2,"MON",IF(WEEKDAY(Table1[[#This Row],[GameDate]])=3,"TUE",IF(WEEKDAY(Table1[[#This Row],[GameDate]])=4,"WED",IF(WEEKDAY(Table1[[#This Row],[GameDate]])=5,"THU",IF(WEEKDAY(Table1[[#This Row],[GameDate]])=6,"FRI", "SAT")))))) -> THU | D13: 2026-10-01 | E13: 21:00 | F13: 2026020012 | G13: MIN | H13: NSH | I13: 1 | J13: 3 | K13: REG | L13: =IF(OR(Table1[[#This Row],[PredictedAwayScore]]=Table1[[#This Row],[PredictedHomeScore]],AND(ISBLANK(Table1[[#This Row],[PredictedAwayScore]]),ISBLANK(Table1[[#This Row],[PredictedHomeScore]]))),"",IF(Table1[[#This Row],[PredictedAwayScore]]>Table1[[#This Row],[PredictedHomeScore]],Table1[[#This Row],[AwayTeam]],Table1[[#This Row],[HomeTeam]])) -> NSH | M13: 2 | N13: 3 | O13: SO | P13: =IF(OR(Table1[[#This Row],[ActualAwayScore]]=Table1[[#This Row],[ActualHomeScore]],AND(ISBLANK(Table1[[#This Row],[ActualAwayScore]]),ISBLANK(Table1[[#This Row],[ActualHomeScore]]))),"",IF(Table1[[#This Row],[ActualAwayScore]]>Table1[[#This Row],[ActualHomeScore]],Table1[[#This Row],[AwayTeam]], Table1[[#This Row],[HomeTeam]])) -> NSH | T13: =IF(Table1[[#This Row],[ActualWinner]]="", "", IF(Table1[[#This Row],[AwayTeam]]=Table1[[#This Row],[ActualWinner]],Table1[[#This Row],[HomeTeam]],Table1[[#This Row],[AwayTeam]])) -> MIN | U13: =Table1[[#This Row],[ActualAwayScore]]-Table1[[#This Row],[PredictedAwayScore]] -> 1 | V13: =Table1[[#This Row],[ActualHomeScore]]-Table1[[#This Row],[PredictedHomeScore]] -> 0 | W13: =(0.8*IF(Table1[[#This Row],[CorrectWinnerPrediction]]=1, 1, 0))+(0.1*IF(Table1[[#This Row],[CorrectAwayScorePrediction]]=1, 1, 0))+(0.1*IF(Table1[[#This Row],[CorrectHomeScorePrediction]]=1, 1, 0)) -> 0.9 | X13: =(0.8*IF(Table1[[#This Row],[CorrectWinnerPrediction]]=1, 1, 0))+(0.1*IF(Table1[[#This Row],[CorrectAwayScorePrediction]]=1, 1, 0))+(0.1*IF(Table1[[#This Row],[CorrectHomeScorePrediction]]=1, 1, 0)) + (0.8 * IF(OR(Table1[[#This Row],[PredictedResult]]="REG",Table1[[#This Row],[CorrectWinnerPrediction]]=1), 0, IF(Table1[[#This Row],[ActualResult]]="OT", 0.85, IF(Table1[[#This Row],[ActualResult]]="SO", 0.95, 0)))) -> 0.9 | Z13: =SUMIF(Table1[GameDate], Table1[[#This Row],[GameDate]], Table1[AwayGameGoalDiff]) -> 3 | AA13: =SUMIF(Table1[GameDate], Table1[[#This Row],[GameDate]], Table1[HomeGameGoalDiff]) -> -4 | AB13: =IF(ISBLANK(Table1[[#This Row],[ActualResult]]), 0, 1) -> 1 | AC13: =IF(ISBLANK(Table1[[#This Row],[ActualResult]]), 0, IF(Table1[[#This Row],[ActualWinner]]=Table1[[#This Row],[PredictedWinner]], 1, 0)) -> 1 | AD13: =IF(Table1[[#This Row],[ActualAwayScore]]>Table1[[#This Row],[PredictedAwayScore]], 0, IF(ISBLANK(Table1[[#This Row],[ActualResult]]), 0, IF(Table1[[#This Row],[ActualAwayScore]]=Table1[[#This Row],[PredictedAwayScore]], 1,0))) -> 0 | AE13: =IF(Table1[[#This Row],[ActualHomeScore]]>Table1[[#This Row],[PredictedHomeScore]], 0, IF(ISBLANK(Table1[[#This Row],[ActualResult]]), 0, IF(Table1[[#This Row],[ActualHomeScore]]=Table1[[#This Row],[PredictedHomeScore]], 1, 0))) -> 1 | AF13: =IF(AND(Table1[[#This Row],[GameIsOver]]=1,Table1[[#This Row],[ActualAwayScore]]=0), 1,0) -> 0 | AG13: =IF(AND(Table1[[#This Row],[GameIsOver]]=1,Table1[[#This Row],[ActualHomeScore]]=0), 1,0) -> 0 | AH13: =IF(Table1[[#This Row],[GameIsOver]]=0,0,IF(Table1[[#This Row],[ActualWinner]]=Table1[[#This Row],[AwayTeam]], 1, 0)) -> 0 | AI13: =IF(Table1[[#This Row],[GameIsOver]]=0,0,IF(Table1[[#This Row],[ActualWinner]]=Table1[[#This Row],[HomeTeam]], 1, 0)) -> 1 | AJ13: =IF(INDEX(Standings!$A$2:$C$33,MATCH(Table1[[#This Row],[AwayTeam]],Standings!$A$2:$A$33,0),2)=INDEX(Standings!$A$2:$C$33,MATCH(Table1[[#This Row],[HomeTeam]],Standings!$A$2:$A$33,0),2),1,0) -> 1 | AK13: =IF(INDEX(Standings!$A$2:$C$33,MATCH(Table1[[#This Row],[AwayTeam]],Standings!$A$2:$A$33,0),3)=INDEX(Standings!$A$2:$C$33,MATCH(Table1[[#This Row],[HomeTeam]],Standings!$A$2:$A$33,0),3),1,0) -> 1 | AL13: =IF(Table1[[#This Row],[InterConf]]=1,IF(Table1[[#This Row],[InterDiv]]=0, 1, 0), 0) -> 0 | AM13: =IF(INDEX(Standings!$A$2:$C$33,MATCH(Table1[[#This Row],[AwayTeam]],Standings!$A$2:$A$33,0),2)<>INDEX(Standings!$A$2:$C$33,MATCH(Table1[[#This Row],[HomeTeam]],Standings!$A$2:$A$33,0),2),1,0) -> 0 | AN13: =INDEX(Table2[AWAY_RECORD], MATCH(Table1[[#This Row],[AwayTeam]],Table2[Team], 0), 0) -> 0-0-1 | AO13: =INDEX(Records!$B$2:$AG$33, MATCH(Table1[[#This Row],[AwayTeam]],Records!$A$2:$A$33, 0), MATCH(Table1[[#This Row],[HomeTeam]],Records!$A$2:$A$33, 0)) -> 0-0-1 | AP13: =INDEX(Table2[HOME_RECORD], MATCH(Table1[[#This Row],[HomeTeam]],Table2[Team], 0), 0) -> 1-0-0 | AQ13: =INDEX(Records!$B$2:$AG$33, MATCH(Table1[[#This Row],[HomeTeam]],Records!$A$2:$A$33, 0), MATCH(Table1[[#This Row],[AwayTeam]],Records!$A$2:$A$33, 0)) -> 1-0-0
